Workbook

Sheet Catalog Master
A1: Group A — Roster Identity | Stone ID | B1: Group A — Roster Identity | Canonical Name | C1: Group A — Roster Identity | Alternate Names | D1: Group A — Roster Identity | Family | E1: Group A — Roster Identity | Species | F1: Group B — Catalog Structure | Collection Tier | G1: Group B — Catalog Structure | Cohort | H1: Group B — Catalog Structure | Catalog Display Order | I1: Group B — Catalog Structure | Navigation Display Order | J1: Group C — Navigation | Previous Stone | K1: Group C — Navigation | Previous Slug | L1: Group C — Navigation | Next Stone | M1: Group C — Navigation | Next Slug | N1: Group C — Navigation | Navigation Verified | O1: Group D — Slug & URL | Slug | P1: Group E — Production Status | Encyclopedia Production Status | Q1: Group F — At a Glance | Primary Chakra | R1: Group F — At a Glance | Secondary Chakra | S1: Group F — At a Glance | Styling Chakra | T1: Group F — At a Glance | Element | U1: Group F — At a Glance | Zodiac | V1: Group F — At a Glance | Encyclopedia Energetic Role | W1: Group F — At a Glance | Energetic Role Icon | X1: Group F — At a Glance | Material Type | Y1: Group F — At a Glance | Color Energy | Z1: Group G — Hero Fields | Best For | AA1: Group G — Hero Fields | Use When | AB1: Group G — Hero Fields | Affirmation | AC1: Group H — Legacy Roles | Energetic Role 1 | AD1: Group H — Legacy Roles | Energetic Role 2 | AE1: Group H — Legacy Roles | Energetic Role 3 | AF1: Group I — Card & Image | Card Properties | AG1: Group I — Card & Image | Image URL | AH1: Group I — Card & Image | Image Filename | AI1: Group I — Card & Image | Image Status | AJ1: Group J — Identity Flags | Exception / Identity Flag | AK1: Group J — Identity Flags | Exception Review Required | AL1: Group J — Identity Flags | Structured Data Status | AM1: Group K — Workflow | Research Status | AN1: Group K — Workflow | Canonical MD Status | AO1: Group K — Workflow | Supabase Status | AP1: Group K — Workflow | Visual QA Status | AQ1: Group K — Workflow | Editorial Owner | AR1: Group K — Workflow | Production Data Version | AS1: Group K — Workflow | Blocker | AT1: Group K — Workflow | Notes
A2: C-0119 | B2: Amethyst | D2: Quartz | E2: Quartz | F2: 1 | G2: 1 | H2: 119 | I2: 119 | J2: Amegreen | K2: amegreen | L2: Ametrine | M2: ametrine | N2: FALSE | O2: amethyst | P2: Full Entry Live | Q2: Third Eye | R2: Crown | S2: Crown | T2: Air | U2: Aquarius | V2: Spiritual Connection | W2: spiritual-connection | X2: Mineral variety | Y2: Violet Purple | Z2: Quiet intuition | AA2: Use when you need to settle your mind and listen beneath the noise. | AB2: I become still enough to hear what matters. | AC2: Calm & Peace | AD2: Protection | AE2: Spiritual Connection | AF2: ["Calm","Intuition","Protection"] | AK2: FALSE | AL2: Confirmed | AM2: Complete | AN2: Approved | AO2: Complete | AP2: Not Started | AQ2: Lyra | AR2: v0.3-2026-06-30 | AT2: Cohort 1 Gate 1 research complete; canonical MD approved by Christie on 2026-06-30. Image, Supabase, and visual QA remain pending.
A3: C-0129 | B3: Black Tourmaline | C3: Schorl | D3: Tourmaline | E3: Schorl | F3: 1 | G3: 1 | H3: 129 | I3: 129 | J3: Black Opal | K3: black-opal | L3: Bloodstone | M3: bloodstone | N3: FALSE | O3: black-tourmaline | P3: Full Entry Live | Q3: Root | S3: Root | T3: Earth | U3: Capricorn | V3: Protection | W3: protection | X3: Mineral | Y3: Black | Z3: Energetic boundaries | AA3: Use when you need to feel anchored, protected, and less affected by the energy around you. | AB3: I remain grounded, clear, and fully within my own boundaries. | AC3: Protection | AD3: Grounding | AF3: ["Protection","Grounding","Boundaries"] | AK3: FALSE | AL3: Confirmed | AM3: Complete | AN3: Approved | AO3: Complete | AP3: Not Started | AQ3: Lyra | AR3: v0.3-2026-06-30 | AT3: Cohort 1 Gate 1 research complete; canonical MD approved by Christie on 2026-06-30. Image, Supabase, and visual QA remain pending.
A4: C-0153 | B4: Carnelian | D4: Aggregate | E4: Chalcedony | F4: 1 | G4: 1 | H4: 153 | I4: 153 | J4: Caribbean Calcite | K4: caribbean-calcite | L4: Cavansite | M4: cavansite | N4: FALSE | O4: carnelian | P4: Full Entry Live | Q4: Sacral | R4: Solar Plexus | S4: Sacral | T4: Fire | U4: Aries · Leo | V4: Vitality | W4: vitality | X4: Mineral variety | Y4: Orange Red | Z4: Creative action | AA4: Use when you feel hesitant, uninspired, or stuck at the edge of beginning. | AB4: I act with courage, warmth, and creative conviction. | AC4: Vitality | AD4: Confidence | AF4: ["Creativity","Confidence","Vitality"] | AK4: FALSE | AL4: Confirmed | AM4: Complete | AN4: Approved | AO4: Complete | AP4: Not Started | AQ4: Lyra | AR4: v0.3-2026-06-30 | AT4: Cohort 1 Gate 1 research complete; canonical MD approved by Christie on 2026-06-30. Image, Supabase, and visual QA remain pending.
A5: C-0121 | B5: Citrine | D5: Quartz | E5: Quartz | F5: 1 | G5: 1 | H5: 121 | I5: 121 | J5: Cinnabrite | K5: cinnabrite | L5: Clear Fluorite | M5: clear-fluorite | N5: FALSE | O5: citrine | P5: MD Approved | Q5: Solar Plexus | R5: Sacral | S5: Solar Plexus | T5: Fire | U5: Aries · Leo | V5: Manifestation | W5: manifestation | X5: Mineral variety | Y5: Golden Yellow | Z5: Empowered momentum | AA5: Use when you need to trust your ability to create, decide, and move forward with confidence. | AB5: I move toward opportunity with confidence, clarity, and generous purpose. | AC5: Confidence | AD5: Manifestation | AF5: ["Abundance","Confidence","Motivation"] | AK5: FALSE | AL5: Confirmed | AM5: Complete | AN5: Approved | AO5: Not Started | AP5: Not Started | AQ5: Lyra | AR5: v0.3-2026-06-30 | AT5: Cohort 1 Gate 1 research complete; canonical MD approved by Christie on 2026-06-30. Image, Supabase, and visual QA remain pending.
A6: C-0105 | B6: Clear Quartz | D6: Quartz | E6: Quartz | F6: 1 | G6: 1 | H6: 105 | I6: 105 | J6: Clear Fluorite | K6: clear-fluorite | L6: Cobaltoan Calcite | M6: cobaltoan-calcite | N6: FALSE | O6: clear-quartz | P6: Full Entry Live | Q6: All Chakras | S6: Crown | T6: Storm | U6: Aries | V6: Amplification | W6: amplification | X6: Mineral | Y6: Colorless | Z6: Clear intention | AA6: Use when you need to clarify your intention and bring scattered energy into alignment. | AB6: I direct my energy clearly toward what matters most. | AC6: Amplification | AD6: Clarity & Focus | AF6: ["Amplification","Clarity","Focus"] | AK6: FALSE | AL6: Confirmed | AM6: Complete | AN6: Approved | AO6: Complete | AP6: Not Started | AQ6: Lyra | AR6: v0.3-2026-06-30 | AT6: Cohort 1 Gate 1 research complete; canonical MD approved by Christie on 2026-06-30. Image, Supabase, and visual QA remain pending.
A7: C-0178 | B7: Green Aventurine | D7: Aventurine | E7: Aventurine | F7: 1 | G7: 1 | H7: 178 | I7: 178 | J7: Green Aragonite | K7: green-aragonite | L7: Green Calcite | M7: green-calcite | N7: FALSE | O7: green-aventurine | P7: Full Entry Live | Q7: Heart | S7: Heart | T7: Earth | U7: Aries · Taurus | V7: Manifestation | W7: manifestation | X7: Rock | Y7: Green | Z7: Fresh starts | AA7: Use when you need encouragement to begin again with a lighter, more hopeful heart. | AB7: I welcome growth, opportunity, and the courage to begin again. | AC7: Grounding | AD7: Joy | AF7: ["Luck","Abundance","Growth"] | AK7: FALSE | AL7: Confirmed | AM7: Complete | AN7: Approved | AO7: Complete | AP7: Not Started | AQ7: Lyra | AR7: v0.3-2026-06-30 | AT7: Cohort 1 Gate 1 research complete; canonical MD approved by Christie on 2026-06-30. Image, Supabase, and visual QA remain pending.
A8: C-0028 | B8: Labradorite | D8: Feldspar | E8: Plagioclase | F8: 1 | G8: 2 | H8: 28 | I8: 28 | J8: Kunzite | K8: kunzite | L8: Laguna Jasper | M8: laguna-jasper | N8: FALSE | O8: labradorite | P8: Not Started | Q8: Third Eye | S8: Third Eye | T8: Air | V8: Transformation | W8: transformation | X8: Mineral | Z8: Intuitive protection | AA8: Use when you need to trust your intuition while staying protected and centered. | AC8: Protection | AD8: Intuition | AF8: ["Intuition","Protection","Transformation"] | AK8: FALSE | AL8: SYNTHESIS COMPLETE | AM8: PASS 2 COMPLETE | AN8: SYNTHESIS COMPLETE | AO8: Not Started | AP8: Not Started | AR8: v0.3-2026-06-29
A9: C-0108 | B9: Rose Quartz | D9: Quartz | E9: Quartz | F9: 1 | G9: 3 | H9: 108 | I9: 108 | J9: Rhyolite | K9: rhyolite | L9: Ruby | M9: ruby | N9: FALSE | O9: rose-quartz | P9: Full Entry Live | Q9: Heart | S9: Heart | X9: Mineral | Z9: Self-compassion | AA9: Use when you need to soften self-criticism and return to a more compassionate center. | AC9: Self-Love | AD9: Heart Healing | AF9: ["Love","Compassion","Healing"] | AK9: FALSE | AL9: Unreviewed | AM9: Complete | AN9: Approved | AO9: Complete | AP9: Not Started | AR9: v0.3-2026-06-29
A10: C-0175 | B10: Selenite | C10: Satin Spar Gypsum | D10: Gypsum | E10: Gypsum | F10: 1 | G10: 3 | H10: 175 | I10: 175 | J10: Scolecite | K10: scolecite | L10: Septarian | M10: septarian | N10: FALSE | O10: selenite | P10: Full Entry Live | Q10: Crown | R10: Third Eye | S10: Crown | X10: Mineral | Z10: Energetic clearing | AA10: Use when you need to clear stagnant energy and bring a room or ritual back to stillness. | AC10: Clarity & Focus | AD10: Spiritual Connection | AF10: ["Purification","Clarity","Peace"] | AK10: FALSE | AL10: Unreviewed | AM10: Complete | AN10: Approved | AO10: Complete | AP10: Not Started | AR10: v0.3-2026-06-29
A11: C-0103 | B11: Smoky Quartz | D11: Quartz | E11: Quartz | F11: 1 | G11: 3 | H11: 103 | I11: 103 | J11: Smoky Citrine | K11: smoky-citrine | L11: Snowflake Obsidian | M11: snowflake-obsidian | N11: FALSE | O11: smoky-quartz | P11: Full Entry Live | Q11: Root | S11: Root | X11: Mineral | Z11: Letting go | AA11: Use when you need to let go of heaviness and come back into your body. | AC11: Grounding | AD11: Protection | AF11: ["Grounding","Protection","Calm"] | AK11: FALSE | AL11: Unreviewed | AM11: Complete | AN11: Approved | AO11: Complete | AP11: Not Started | AR11: v0.3-2026-06-29
A12: C-0139 | B12: Black Obsidian | C12: Obsidian | D12: Obsidian | E12: Obsidian | F12: 1 | G12: 1 | H12: 139 | I12: 139 | J12: Black Moonstone | K12: black-moonstone | L12: Black Opal | M12: black-opal | N12: FALSE | O12: black-obsidian | P12: MD Approved | Q12: Root | S12: Root | T12: Earth | U12: Scorpio · Capricorn | V12: Protection | W12: protection | X12: Mineraloid | Y12: Black | Z12: Honest release | AA12: Use when you are ready to face an uncomfortable truth instead of continuing to avoid it. | AB12: I face what is true and release what no longer belongs. | AC12: Protection | AD12: Clarity & Focus | AF12: ["Protection","Grounding","Truth"] | AK12: FALSE | AL12: Confirmed | AM12: Complete | AN12: Approved | AO12: Not Started | AP12: Not Started | AQ12: Lyra | AR12: v0.3-2026-06-30 | AT12: Cohort 1 Gate 1 research complete; canonical MD approved by Christie on 2026-06-30. Image, Supabase, and visual QA remain pending.
A13: C-0041 | B13: Hematite | C13: Specular Hematite | D13: Iron Minerals | E13: Hematite | F13: 1 | G13: 2 | H13: 41 | I13: 41 | J13: Heliodor | K13: heliodor | L13: Hematoid Quartz | M13: hematoid-quartz | N13: FALSE | O13: hematite | P13: Full Entry Live | Q13: Root | S13: Root | X13: Mineral | Z13: Practical steadiness | AA13: Use when you feel scattered, unsteady, or disconnected from the task directly in front of you. | AC13: Grounding | AD13: Confidence | AF13: ["Grounding","Embodiment","Stability"] | AK13: FALSE | AL13: Unreviewed | AM13: Complete | AN13: Approved | AO13: Complete | AP13: Not Started | AR13: v0.3-2026-06-29
A14: C-0188 | B14: Lapis Lazuli | D14: Aggregate | E14: Lazurite; Calcite; Pyrite | F14: 1 | G14: 2 | H14: 188 | I14: 188 | J14: Laguna Jasper | K14: laguna-jasper | L14: Larimar | M14: larimar | N14: FALSE | O14: lapis-lazuli | P14: Not Started | Q14: Third Eye | R14: Throat | S14: Third Eye | T14: Water | V14: Intuition | W14: intuition | X14: Rock | Z14: Authentic expression | AA14: Use when you need to understand what you truly think before explaining it to someone else. | AC14: Clarity & Focus | AD14: Communication | AE14: Intuition | AF14: ["Wisdom","Truth","Communication"] | AK14: FALSE | AL14: SYNTHESIS COMPLETE | AM14: PASS 2 COMPLETE | AN14: SYNTHESIS COMPLETE | AO14: Not Started | AP14: Not Started | AR14: v0.3-2026-06-29
A15: C-0254 | B15: Lepidolite | D15: Silicates | E15: Lepidolite | F15: 1 | G15: 2 | H15: 254 | I15: 254 | J15: Lepidocrocite | K15: lepidocrocite | L15: Libyan Desert Glass | M15: libyan-desert-glass | N15: FALSE | O15: lepidolite | P15: Not Started | Q15: Third Eye | R15: Heart | S15: Third Eye | T15: Water | V15: Emotional Regulation | W15: emotional-regulation | X15: Mineral | Z15: Gentle transition | AA15: Use when change is happening faster than your emotions can comfortably process it. | AC15: Calm & Peace | AD15: Emotional Balance | AF15: ["Calm","Balance","Acceptance"] | AK15: FALSE | AL15: SYNTHESIS COMPLETE | AM15: PASS 2 COMPLETE | AN15: SYNTHESIS COMPLETE | AO15: Not Started | AP15: Not Started | AR15: v0.3-2026-06-29
A16: C-0020 | B16: Malachite | D16: Copper Minerals | E16: Malachite | F16: 1 | G16: 2 | H16: 20 | I16: 20 | J16: Mahogany Obsidian | K16: mahogany-obsidian | L16: Mangano Calcite | M16: mangano-calcite | N16: FALSE | O16: malachite | P16: Full Entry Live | Q16: Heart | R16: Solar Plexus | S16: Heart | X16: Mineral | Z16: Courageous change | AA16: Use when you know something needs to change but keep circling the same familiar pattern. | AC16: Transformation | AD16: Protection | AF16: ["Transformation","Courage","Protection"] | AK16: FALSE | AL16: Unreviewed | AM16: Complete | AN16: Approved | AO16: Complete | AP16: Not Started | AR16: v0.3-2026-06-29
A17: C-0162 | B17: Moonstone | D17: Feldspar | E17: Orthoclase | F17: 1 | G17: 2 | H17: 162 | I17: 162 | J17: Mookaite Jasper | K17: mookaite-jasper | L17: Morganite | M17: morganite | N17: FALSE | O17: moonstone | P17: Full Entry Live | Q17: Crown | R17: Third Eye | S17: Crown | X17: Mineral | Z17: Emotional transitions | AA17: Use when you are moving through a transition and need permission to respond rather than force. | AC17: Intuition | AF17: ["Intuition","Balance","Dreams"] | AK17: FALSE | AL17: Unreviewed | AM17: Complete | AN17: Approved | AO17: Complete | AP17: Not Started | AR17: v0.3-2026-06-29
A18: C-0137 | B18: Pyrite | C18: Fool's Gold | D18: Sulfides | E18: Pyrite | F18: 1 | G18: 2 | H18: 137 | I18: 137 | J18: Purpurite | K18: purpurite | L18: Pyromorphite | M18: pyromorphite | N18: FALSE | O18: pyrite | P18: Not Started | Q18: Solar Plexus | R18: Root | S18: Solar Plexus | T18: Earth | V18: Manifestation | W18: manifestation | X18: Mineral | Z18: Decisive action | AA18: Use when you need to stop circling an opportunity and begin acting with greater confidence and structure. | AC18: Confidence | AD18: Protection | AE18: Manifestation | AF18: ["Confidence","Abundance","Protection"] | AK18: FALSE | AL18: SYNTHESIS COMPLETE | AM18: PASS 2 COMPLETE | AN18: SYNTHESIS COMPLETE | AO18: Not Started | AP18: Not Started | AR18: v0.3-2026-06-29
A19: C-0030 | B19: Rainbow Moonstone | C19: White Labradorite | D19: Feldspar | E19: Plagioclase | F19: 1 | G19: 3 | H19: 30 | I19: 30 | J19: Rainbow Fluorite | K19: rainbow-fluorite | L19: Rainbow Obsidian | M19: rainbow-obsidian | N19: FALSE | O19: rainbow-moonstone | P19: Full Entry Live | Q19: Crown | S19: Crown | X19: Mineral variety | Z19: Luminous protection | AA19: Use when you want to remain open and intuitive without absorbing everything around you. | AC19: Intuition | AD19: Emotional Balance | AF19: ["Intuition","Protection","Balance"] | AK19: FALSE | AL19: Unreviewed | AM19: Complete | AN19: Approved | AO19: Complete | AP19: Not Started | AR19: v0.3-2026-06-29
A20: C-0218 | B20: Sodalite | D20: Silicates | E20: Sodalite | F20: 1 | G20: 3 | H20: 218 | I20: 218 | J20: Snowflake Obsidian | K20: snowflake-obsidian | L20: Spectrolite | M20: spectrolite | N20: FALSE | O20: sodalite | P20: Full Entry Live | Q20: Throat | R20: Third Eye | S20: Throat | X20: Mineral | Z20: Clear thinking | AA20: Use when you need to organize your thoughts and speak from a calm, truthful place. | AC20: Clarity & Focus | AD20: Communication | AE20: Calm & Peace | AF20: ["Clarity","Communication","Truth"] | AK20: FALSE | AL20: Unreviewed | AM20: Complete | AN20: Approved | AO20: Complete | AP20: Not Started | AR20: v0.3-2026-06-29
A21: C-0029 | B21: Sunstone | D21: Feldspar | E21: Plagioclase | F21: 1 | G21: 3 | H21: 29 | I21: 29 | J21: Sulfur | K21: sulfur | L21: Super Seven | M21: super-seven | N21: FALSE | O21: sunstone | P21: Full Entry Live | Q21: Sacral | R21: Solar Plexus | S21: Sacral | X21: Mineral | Z21: Visible confidence | AA21: Use when you are ready to be more visible but fear of judgment is making you dim your natural enthusiasm. | AC21: Confidence | AD21: Vitality | AF21: ["Confidence","Joy","Independence"] | AK21: FALSE | AL21: Unreviewed | AM21: Complete | AN21: Approved | AO21: Complete | AP21: Not Started | AR21: v0.3-2026-06-29
A22: C-0025 | B22: Amazonite | D22: Feldspar | E22: Microcline | F22: 1 | G22: 1 | H22: 25 | I22: 25 | J22: Alexandrite | K22: alexandrite | L22: Amber | M22: amber | N22: FALSE | O22: amazonite | P22: Full Entry Live | Q22: Heart | R22: Throat | S22: Heart | T22: Water | U22: Virgo | V22: Emotional Regulation | W22: emotional-regulation | X22: Mineral variety | Y22: Blue Green | Z22: Calm expression | AA22: Use when you need to say what is true without becoming overwhelmed, defensive, or overly forceful. | AB22: I speak my truth with calm, clarity, and care. | AC22: Communication | AD22: Protection | AF22: ["Communication","Truth","Calm"] | AK22: FALSE | AL22: Confirmed | AM22: Complete | AN22: Approved | AO22: Complete | AP22: Not Started | AQ22: Lyra | AR22: v0.3-2026-06-30 | AT22: Cohort 1 Gate 1 research complete; canonical MD approved by Christie on 2026-06-30. Image, Supabase, and visual QA remain pending.
A23: C-0063 | B23: Black Kyanite | D23: Kyanite | E23: Kyanite | F23: 1 | G23: 1 | H23: 63 | I23: 63 | J23: Black Chalcedony | K23: black-chalcedony | L23: Black Moonstone | M23: black-moonstone | N23: FALSE | O23: black-kyanite | P23: MD Approved | Q23: Root | S23: Root | T23: Storm | U23: Aries · Taurus | V23: Protection | W23: protection | X23: Mineral | Y23: Black | Z23: Boundary clearing | AA23: Use when you need to make a clean energetic or emotional separation without continuing to revisit the same decision. | AB23: I clear what is complete and return fully to my own center. | AC23: Protection | AD23: Transformation | AF23: ["Protection","Purification","Boundaries"] | AK23: FALSE | AL23: Confirmed | AM23: Complete | AN23: Approved | AO23: Not Started | AP23: Not Started | AQ23: Lyra | AR23: v0.3-2026-06-30 | AT23: Cohort 1 Gate 1 research complete; canonical MD approved by Christie on 2026-06-30. Image, Supabase, and visual QA remain pending.
A24: C-0151 | B24: Bloodstone | D24: Aggregate | E24: Chalcedony | F24: 1 | G24: 1 | H24: 151 | I24: 151 | J24: Black Tourmaline | K24: black-tourmaline | L24: Blue Apatite | M24: blue-apatite | N24: FALSE | O24: bloodstone | P24: MD Approved | Q24: Root | S24: Root | T24: Earth | U24: Gemini · Scorpio | V24: Vitality | W24: vitality | X24: Mineral variety | Y24: Deep Green · Red | Z24: Steady courage | AA24: Use when a demanding situation requires persistence, composure, and the willingness to keep showing up. | AB24: I meet pressure with courage, endurance, and a steady heart. | AC24: Grounding | AD24: Confidence | AF24: ["Courage","Endurance","Vitality"] | AK24: FALSE | AL24: Confirmed | AM24: Complete | AN24: Approved | AO24: Not Started | AP24: Not Started | AQ24: Lyra | AR24: v0.3-2026-06-30 | AT24: Cohort 1 Gate 1 research complete; canonical MD approved by Christie on 2026-06-30. Image, Supabase, and visual QA remain pending.
A25: C-0241 | B25: Howlite | D25: Other Mineral | E25: Howlite | F25: 1 | G25: 2 | H25: 241 | I25: 241 | J25: Honey Calcite | K25: honey-calcite | L25: Hypersthene | M25: hypersthene | N25: FALSE | O25: howlite | P25: Not Started | Q25: Crown | S25: Crown | T25: Air | V25: Calm & Peace | W25: calm-peace | X25: Mineral | Z25: Mental stillness | AA25: Use when you need to soften mental noise and return to steadiness before reacting. | AC25: Calm & Peace | AF25: ["Calm","Peace","Rest"] | AK25: FALSE | AL25: SYNTHESIS COMPLETE | AM25: PASS 2 COMPLETE | AN25: SYNTHESIS COMPLETE | AO25: Not Started | AP25: Not Started | AR25: v0.3-2026-06-29
A26: C-0077 | B26: Moss Agate | D26: Quartz | E26: Quartz | F26: 1 | G26: 2 | H26: 77 | I26: 77 | J26: Morganite | K26: morganite | L26: Muscovite | M26: muscovite | N26: FALSE | O26: moss-agate | P26: Not Started | Q26: Heart | R26: Root | S26: Heart | T26: Earth | V26: Manifestation | W26: manifestation | X26: Mineral | Z26: Steady renewal | AA26: Use when you need encouragement to grow slowly without mistaking gradual progress for failure. | AC26: Grounding | AD26: Manifestation | AF26: ["Growth","Grounding","Stability"] | AK26: FALSE | AL26: SYNTHESIS COMPLETE | AM26: PASS 2 COMPLETE | AN26: SYNTHESIS COMPLETE | AO26: Not Started | AP26: Not Started | AR26: v0.3-2026-06-29
A27: C-0095 | B27: Ocean Jasper | D27: Quartz | E27: Quartz | F27: 1 | G27: 2 | H27: 95 | I27: 95 | J27: Nuumite | K27: nuumite | L27: Onyx | M27: onyx | N27: FALSE | O27: ocean-jasper | P27: Not Started | Q27: Heart | R27: Throat | S27: Heart | T27: Water | V27: Calm & Peace | W27: calm-peace | X27: Mineral | Z27: Emotional rhythm | AA27: Use when you are judging yourself for not feeling, healing, or progressing at the same pace every day. | AC27: Joy | AD27: Emotional Balance | AF27: ["Joy","Balance","Renewal"] | AK27: FALSE | AL27: SYNTHESIS COMPLETE | AM27: PASS 2 COMPLETE | AN27: SYNTHESIS COMPLETE | AO27: Not Started | AP27: Not Started | AR27: v0.3-2026-06-29
A28: C-0035 | B28: Rainbow Fluorite | D28: Fluorite | E28: Fluorite | F28: 1 | G28: 3 | H28: 35 | I28: 35 | J28: Que Sera Stone | K28: que-sera-stone | L28: Rainbow Moonstone | M28: rainbow-moonstone | N28: FALSE | O28: rainbow-fluorite | P28: Full Entry Live | Q28: Third Eye | S28: Third Eye | X28: Mineral | Z28: Mental organization | AA28: Use when you have too many thoughts, options, or inputs competing for your attention. | AC28: Clarity & Focus | AD28: Transformation | AF28: ["Clarity","Focus","Balance"] | AK28: FALSE | AL28: Unreviewed | AM28: Complete | AN28: Approved | AO28: Complete | AP28: Not Started | AR28: v0.3-2026-06-29
A29: C-0099 | B29: Red Jasper | D29: Quartz | E29: Quartz | F29: 1 | G29: 3 | H29: 99 | I29: 99 | J29: Red Calcite | K29: red-calcite | L29: Red Tiger's Eye | M29: red-tiger-s-eye | N29: FALSE | O29: red-jasper | P29: Full Entry Live | Q29: Root | S29: Root | X29: Mineral variety | Z29: Sustained effort | AA29: Use when you need steady endurance more than a sudden burst of motivation. | AC29: Vitality | AD29: Grounding | AF29: ["Grounding","Endurance","Vitality"] | AK29: FALSE | AL29: Unreviewed | AM29: Complete | AN29: Approved | AO29: Complete | AP29: Not Started | AR29: v0.3-2026-06-29
A30: C-0168 | B30: Tiger's Eye | D30: Tiger's Eye | E30: Tiger's Eye | F30: 1 | G30: 3 | H30: 168 | I30: 168 | J30: Gold Sheen Obsidian | K30: gold-sheen-obsidian | L30: Golden Healer Quartz | M30: golden-healer-quartz | N30: FALSE | O30: tigers-eye | P30: Full Entry Live | Q30: Solar Plexus | R30: Root | S30: Solar Plexus | X30: Mineral variety | Z30: Grounded confidence | AA30: Use when you need to make a confident decision without becoming reckless or second-guessing yourself. | AC30: Grounding | AD30: Confidence | AF30: ["Grounding","Confidence","Discernment"] | AK30: FALSE | AL30: Unreviewed | AM30: Complete | AN30: Approved | AO30: Complete | AP30: Not Started | AR30: v0.3-2026-06-29
A31: C-0060 | B31: Unakite | D31: Aggregate | E31: Unakite | F31: 1 | G31: 3 | H31: 60 | I31: 60 | J31: Ulexite | K31: ulexite | L31: Unicorn Stone | M31: unicorn-stone | N31: FALSE | O31: unakite | P31: Full Entry Live | Q31: Heart | S31: Heart | X31: Rock | Z31: Emotional integration | AA31: Use when an old experience is still shaping your reactions and you want to respond from the present instead. | AC31: Emotional Balance | AD31: Heart Healing | AE31: Grounding | AF31: ["Healing","Integration","Grounding"] | AK31: FALSE | AL31: Unreviewed | AM31: Complete | AN31: Approved | AO31: Complete | AP31: Not Started | AR31: v0.3-2026-06-29
A32: C-9002 | B32: Chocolate Calcite | D32: Calcite | E32: Calcite | F32: 3 | G32: 18 | H32: 0 | I32: 0 | J32: Chiastolite | K32: chiastolite | L32: Chrysanthemum Stone | M32: chrysanthemum-stone | N32: FALSE | O32: chocolate-calcite | P32: Not Started | Q32: Root | S32: Root | X32: Mineral | Z32: Grounded comfort | AA32: Use when stress has pulled you away from your body and you need something steady, familiar, and uncomplicated. | AC32: Grounding | AD32: Vitality | AE32: Confidence | AF32: ["Grounding","Stability","Vitality"] | AK32: FALSE | AL32: Unreviewed | AM32: Not Started | AN32: Not Started | AO32: Not Started | AP32: Not Started | AR32: v0.3-2026-06-29
A33: C-0295 | B33: Clear Fluorite | D33: Fluorite | E33: Fluorite | F33: 3 | G33: 19 | H33: 0 | I33: 0 | J33: Citrine | K33: citrine | L33: Clear Quartz | M33: clear-quartz | N33: FALSE | O33: clear-fluorite | P33: Not Started | Q33: Crown | R33: Third Eye | S33: Crown | X33: Mineral | Z33: Mental simplicity | AA33: Use when too much information has made a decision feel more complicated than it needs to be. | AC33: Clarity & Focus | AD33: Protection | AF33: ["Clarity","Focus","Purification"] | AK33: FALSE | AL33: Unreviewed | AM33: Not Started | AN33: Not Started | AO33: Not Started | AP33: Not Started | AR33: v0.3-2026-06-29
A34: C-0124 | B34: Crackle Quartz | C34: Ice Quartz | D34: Quartz | E34: Quartz | F34: 3 | G34: 19 | H34: 124 | I34: 124 | J34: Covellite | K34: covellite | L34: Crazy Lace Agate | M34: crazy-lace-agate | N34: FALSE | O34: crackle-quartz | P34: Not Started | Q34: Crown | S34: Crown | X34: Mineral | Z34: Pattern release | AA34: Use when you feel ready to interrupt an old pattern and create space for a different response. | AC34: Joy | AF34: ["Transformation","Energy","Uplift"] | AK34: FALSE | AL34: Unreviewed | AM34: Not Started | AN34: Not Started | AO34: Not Started | AP34: Not Started | AR34: v0.3-2026-06-29
A35: C-0073 | B35: Druzy Agate | D35: Quartz | E35: Quartz | F35: 3 | G35: 19 | H35: 73 | I35: 73 | J35: Dream Quartz | K35: dream-quartz | L35: Dumortierite | M35: dumortierite | N35: FALSE | O35: druzy-agate | P35: Not Started | Q35: Crown | S35: Crown | X35: Mineral | Z35: Renewed possibility | AA35: Use when your attention has narrowed around problems and you need help noticing what is still open, beautiful, or unfinished. | AC35: Amplification | AD35: Clarity & Focus | AF35: ["Amplification","Joy","Clarity"] | AK35: FALSE | AL35: Unreviewed | AM35: Not Started | AN35: Not Started | AO35: Not Started | AP35: Not Started | AR35: v0.3-2026-06-29
A36: C-0125 | B36: Milky Quartz | D36: Quartz | E36: Quartz | F36: 3 | G36: 23 | H36: 125 | I36: 125 | J36: Meteorite | K36: meteorite | L36: Moldavite | M36: moldavite | N36: FALSE | O36: milky-quartz | P36: Not Started | Q36: Crown | S36: Crown | X36: Mineral | Z36: Gentle steadiness | AA36: Use when you need quiet support but do not want an intense or highly stimulating stone. | AC36: Calm & Peace | AD36: Clarity & Focus | AF36: ["Calm","Clarity","Stability"] | AK36: FALSE | AL36: Unreviewed | AM36: Not Started | AN36: Not Started | AO36: Not Started | AP36: Not Started | AR36: v0.3-2026-06-29
A37: C-0179 | B37: Pink Aventurine | D37: Aventurine | E37: Aventurine | F37: 3 | G37: 24 | H37: 179 | I37: 179 | J37: Pink Aragonite | K37: pink-aragonite | L37: Pink Chalcedony | M37: pink-chalcedony | N37: FALSE | O37: pink-aventurine | P37: Not Started | Q37: Heart | S37: Heart | X37: Rock | Z37: Encouraged confidence | AA37: Use when you need motivation but respond better to encouragement than pressure. | AC37: Grounding | AD37: Calm & Peace | AF37: ["Confidence","Compassion","Motivation"] | AK37: FALSE | AL37: Unreviewed | AM37: Not Started | AN37: Not Started | AO37: Not Started | AP37: Not Started | AR37: v0.3-2026-06-29
A38: C-0033 | B38: Pink Fluorite | D38: Fluorite | E38: Fluorite | F38: 3 | G38: 24 | H38: 33 | I38: 33 | J38: Pink Chalcedony | K38: pink-chalcedony | L38: Pink Halite | M38: pink-halite | N38: FALSE | O38: pink-fluorite | P38: Not Started | Q38: Heart | R38: Crown | S38: Heart | X38: Mineral | Z38: Compassionate perspective | AA38: Use when you need to understand an emotional situation clearly without hardening yourself against it. | AC38: Emotional Balance | AD38: Self-Love | AF38: ["Compassion","Clarity","Balance"] | AK38: FALSE | AL38: Unreviewed | AM38: Not Started | AN38: Not Started | AO38: Not Started | AP38: Not Started | AR38: v0.3-2026-06-29
A39: C-0180 | B39: Red Aventurine | D39: Aventurine | E39: Aventurine | F39: 3 | G39: 24 | H39: 180 | I39: 180 | J39: Rainbow Obsidian | K39: rainbow-obsidian | L39: Red Calcite | M39: red-calcite | N39: FALSE | O39: red-aventurine | P39: Not Started | Q39: Sacral | R39: Root | S39: Sacral | X39: Rock | Z39: Persistent action | AA39: Use when you need motivation that will last beyond the excitement of starting. | AC39: Grounding | AD39: Vitality | AF39: ["Motivation","Endurance","Vitality"] | AK39: FALSE | AL39: Unreviewed | AM39: Not Started | AN39: Not Started | AO39: Not Started | AP39: Not Started | AR39: v0.3-2026-06-29
A40: C-0365 | B40: Super Seven | C40: Melody Stone; Sacred Seven | D40: Quartz | E40: Quartz + Inclusions | F40: 3 | G40: 26 | H40: 0 | I40: 0 | J40: Sunstone | K40: sunstone | L40: Tangerine Quartz | M40: tangerine-quartz | N40: FALSE | O40: super-seven | P40: Not Started | Q40: Crown | S40: Crown | X40: Mineral | Z40: Energetic integration | AA40: Use when you are processing several emotions, insights, or energetic influences at the same time. | AC40: Amplification | AD40: Spiritual Connection | AF40: ["Amplification","Integration","Intuition"] | AK40: FALSE | AL40: Unreviewed | AM40: Not Started | AN40: Not Started | AO40: Not Started | AP40: Not Started | AR40: v0.3-2026-06-29
...

Sheet Controlled Vocabularies
A1: Collection Tier | B1: Material Type | C1: Chakra (Primary/Secondary) | D1: Styling Chakra | E1: Element | F1: Zodiac | G1: Encyclopedia Energetic Role | H1: Encyclopedia Production Status | I1: Research Status | J1: Canonical MD Status | K1: Supabase Status | L1: Visual QA Status | M1: Structured Data Status | N1: Editorial Owner | O1: Exception Review Required | P1: Exception Type
A2: 1 | B2: Mineral | C2: Root | D2: Crown | E2: Air | F2: Aries | G2: Grounding | H2: Full Entry Live | I2: Complete | J2: Approved | K2: Complete | L2: Not Started | M2: Confirmed | N2: Claude Chat | O2: TRUE | P2: Rock
A3: 2 | B3: Mineral variety | C3: Sacral | D3: Heart | E3: Earth | F3: Taurus | G3: Protection | H3: MD Approved | I3: Not Started | J3: Not Started | K3: Not Started | M3: SYNTHESIS COMPLETE | N3: Lyra | O3: FALSE | P3: Mineraloid
A4: 3 | B4: Rock | C4: Solar Plexus | D4: Root | E4: Fire | F4: Gemini | G4: Vitality | H4: Not Started | I4: PASS 2 COMPLETE | J4: SYNTHESIS COMPLETE | M4: Unreviewed | P4: Mineral aggregate
A5: 4 | B5: Mineraloid | C5: Heart | D5: Sacral | E5: Storm | F5: Cancer | G5: Heart Healing | P5: Organic material
B6: Organic material | C6: Throat | D6: Solar Plexus | E6: Water | F6: Leo | G6: Calm & Peace | P6: Fossil
B7: Mineral aggregate | C7: Third Eye | D7: Third Eye | F7: Virgo | G7: Emotional Regulation | P7: Composite
B8: Composite | C8: Crown | D8: Throat | F8: Libra | G8: Clarity & Focus | P8: Man-made
B9: Man-made | C9: All Chakras | F9: Scorpio | G9: Intuition | P9: Treated material
B10: Fossil | C10: Earth Star | F10: Sagittarius | G10: Spiritual Connection | P10: Trade name
C11: Soul Star | F11: Capricorn | G11: Transformation | P11: Locality variety
F12: Aquarius | G12: Manifestation | P12: Mixed material
F13: Pisces | G13: Amplification | P13: Disputed identity
F14: Aries · Leo | P14: Specialist nomenclature review
F15: Aries · Taurus
F16: Gemini · Scorpio
F17: Scorpio · Capricorn

Sheet Foundation Live Checklist
A1: Stone ID | B1: Canonical Name | C1: Slug | D1: Collection Tier | E1: Has Primary Chakra | F1: Has Styling Chakra | G1: Has Material Type | H1: Has Encyclopedia Energetic Role | I1: Has Hero Foundation (Best For/Use When/Affirmation) | J1: Navigation Verified | K1: Structured Data Status | L1: Foundation Ready
A2: ='Catalog Master'!A2 | B2: ='Catalog Master'!B2 | C2: ='Catalog Master'!O2 | D2: ='Catalog Master'!F2 | E2: =IF('Catalog Master'!Q2<>"","Y","N") | F2: =IF('Catalog Master'!S2<>"","Y","N") | G2: =IF('Catalog Master'!X2<>"","Y","N") | H2: =IF('Catalog Master'!V2<>"","Y","N") | I2: =IF(AND('Catalog Master'!Z2<>"",'Catalog Master'!AA2<>"",'Catalog Master'!AB2<>""),"Y","N") | J2: ='Catalog Master'!N2 | K2: ='Catalog Master'!AL2 | L2: =IF(AND(E2="Y",F2="Y",G2="Y",H2="Y",I2="Y"),"Y","N")
A3: ='Catalog Master'!A3 | B3: ='Catalog Master'!B3 | C3: ='Catalog Master'!O3 | D3: ='Catalog Master'!F3 | E3: =IF('Catalog Master'!Q3<>"","Y","N") | F3: =IF('Catalog Master'!S3<>"","Y","N") | G3: =IF('Catalog Master'!X3<>"","Y","N") | H3: =IF('Catalog Master'!V3<>"","Y","N") | I3: =IF(AND('Catalog Master'!Z3<>"",'Catalog Master'!AA3<>"",'Catalog Master'!AB3<>""),"Y","N") | J3: ='Catalog Master'!N3 | K3: ='Catalog Master'!AL3 | L3: =IF(AND(E3="Y",F3="Y",G3="Y",H3="Y",I3="Y"),"Y","N")
A4: ='Catalog Master'!A4 | B4: ='Catalog Master'!B4 | C4: ='Catalog Master'!O4 | D4: ='Catalog Master'!F4 | E4: =IF('Catalog Master'!Q4<>"","Y","N") | F4: =IF('Catalog Master'!S4<>"","Y","N") | G4: =IF('Catalog Master'!X4<>"","Y","N") | H4: =IF('Catalog Master'!V4<>"","Y","N") | I4: =IF(AND('Catalog Master'!Z4<>"",'Catalog Master'!AA4<>"",'Catalog Master'!AB4<>""),"Y","N") | J4: ='Catalog Master'!N4 | K4: ='Catalog Master'!AL4 | L4: =IF(AND(E4="Y",F4="Y",G4="Y",H4="Y",I4="Y"),"Y","N")
A5: ='Catalog Master'!A5 | B5: ='Catalog Master'!B5 | C5: ='Catalog Master'!O5 | D5: ='Catalog Master'!F5 | E5: =IF('Catalog Master'!Q5<>"","Y","N") | F5: =IF('Catalog Master'!S5<>"","Y","N") | G5: =IF('Catalog Master'!X5<>"","Y","N") | H5: =IF('Catalog Master'!V5<>"","Y","N") | I5: =IF(AND('Catalog Master'!Z5<>"",'Catalog Master'!AA5<>"",'Catalog Master'!AB5<>""),"Y","N") | J5: ='Catalog Master'!N5 | K5: ='Catalog Master'!AL5 | L5: =IF(AND(E5="Y",F5="Y",G5="Y",H5="Y",I5="Y"),"Y","N")
A6: ='Catalog Master'!A6 | B6: ='Catalog Master'!B6 | C6: ='Catalog Master'!O6 | D6: ='Catalog Master'!F6 | E6: =IF('Catalog Master'!Q6<>"","Y","N") | F6: =IF('Catalog Master'!S6<>"","Y","N") | G6: =IF('Catalog Master'!X6<>"","Y","N") | H6: =IF('Catalog Master'!V6<>"","Y","N") | I6: =IF(AND('Catalog Master'!Z6<>"",'Catalog Master'!AA6<>"",'Catalog Master'!AB6<>""),"Y","N") | J6: ='Catalog Master'!N6 | K6: ='Catalog Master'!AL6 | L6: =IF(AND(E6="Y",F6="Y",G6="Y",H6="Y",I6="Y"),"Y","N")
A7: ='Catalog Master'!A7 | B7: ='Catalog Master'!B7 | C7: ='Catalog Master'!O7 | D7: ='Catalog Master'!F7 | E7: =IF('Catalog Master'!Q7<>"","Y","N") | F7: =IF('Catalog Master'!S7<>"","Y","N") | G7: =IF('Catalog Master'!X7<>"","Y","N") | H7: =IF('Catalog Master'!V7<>"","Y","N") | I7: =IF(AND('Catalog Master'!Z7<>"",'Catalog Master'!AA7<>"",'Catalog Master'!AB7<>""),"Y","N") | J7: ='Catalog Master'!N7 | K7: ='Catalog Master'!AL7 | L7: =IF(AND(E7="Y",F7="Y",G7="Y",H7="Y",I7="Y"),"Y","N")
A8: ='Catalog Master'!A8 | B8: ='Catalog Master'!B8 | C8: ='Catalog Master'!O8 | D8: ='Catalog Master'!F8 | E8: =IF('Catalog Master'!Q8<>"","Y","N") | F8: =IF('Catalog Master'!S8<>"","Y","N") | G8: =IF('Catalog Master'!X8<>"","Y","N") | H8: =IF('Catalog Master'!V8<>"","Y","N") | I8: =IF(AND('Catalog Master'!Z8<>"",'Catalog Master'!AA8<>"",'Catalog Master'!AB8<>""),"Y","N") | J8: ='Catalog Master'!N8 | K8: ='Catalog Master'!AL8 | L8: =IF(AND(E8="Y",F8="Y",G8="Y",H8="Y",I8="Y"),"Y","N")
A9: ='Catalog Master'!A9 | B9: ='Catalog Master'!B9 | C9: ='Catalog Master'!O9 | D9: ='Catalog Master'!F9 | E9: =IF('Catalog Master'!Q9<>"","Y","N") | F9: =IF('Catalog Master'!S9<>"","Y","N") | G9: =IF('Catalog Master'!X9<>"","Y","N") | H9: =IF('Catalog Master'!V9<>"","Y","N") | I9: =IF(AND('Catalog Master'!Z9<>"",'Catalog Master'!AA9<>"",'Catalog Master'!AB9<>""),"Y","N") | J9: ='Catalog Master'!N9 | K9: ='Catalog Master'!AL9 | L9: =IF(AND(E9="Y",F9="Y",G9="Y",H9="Y",I9="Y"),"Y","N")
A10: ='Catalog Master'!A10 | B10: ='Catalog Master'!B10 | C10: ='Catalog Master'!O10 | D10: ='Catalog Master'!F10 | E10: =IF('Catalog Master'!Q10<>"","Y","N") | F10: =IF('Catalog Master'!S10<>"","Y","N") | G10: =IF('Catalog Master'!X10<>"","Y","N") | H10: =IF('Catalog Master'!V10<>"","Y","N") | I10: =IF(AND('Catalog Master'!Z10<>"",'Catalog Master'!AA10<>"",'Catalog Master'!AB10<>""),"Y","N") | J10: ='Catalog Master'!N10 | K10: ='Catalog Master'!AL10 | L10: =IF(AND(E10="Y",F10="Y",G10="Y",H10="Y",I10="Y"),"Y","N")
A11: ='Catalog Master'!A11 | B11: ='Catalog Master'!B11 | C11: ='Catalog Master'!O11 | D11: ='Catalog Master'!F11 | E11: =IF('Catalog Master'!Q11<>"","Y","N") | F11: =IF('Catalog Master'!S11<>"","Y","N") | G11: =IF('Catalog Master'!X11<>"","Y","N") | H11: =IF('Catalog Master'!V11<>"","Y","N") | I11: =IF(AND('Catalog Master'!Z11<>"",'Catalog Master'!AA11<>"",'Catalog Master'!AB11<>""),"Y","N") | J11: ='Catalog Master'!N11 | K11: ='Catalog Master'!AL11 | L11: =IF(AND(E11="Y",F11="Y",G11="Y",H11="Y",I11="Y"),"Y","N")
A12: ='Catalog Master'!A12 | B12: ='Catalog Master'!B12 | C12: ='Catalog Master'!O12 | D12: ='Catalog Master'!F12 | E12: =IF('Catalog Master'!Q12<>"","Y","N") | F12: =IF('Catalog Master'!S12<>"","Y","N") | G12: =IF('Catalog Master'!X12<>"","Y","N") | H12: =IF('Catalog Master'!V12<>"","Y","N") | I12: =IF(AND('Catalog Master'!Z12<>"",'Catalog Master'!AA12<>"",'Catalog Master'!AB12<>""),"Y","N") | J12: ='Catalog Master'!N12 | K12: ='Catalog Master'!AL12 | L12: =IF(AND(E12="Y",F12="Y",G12="Y",H12="Y",I12="Y"),"Y","N")
A13: ='Catalog Master'!A13 | B13: ='Catalog Master'!B13 | C13: ='Catalog Master'!O13 | D13: ='Catalog Master'!F13 | E13: =IF('Catalog Master'!Q13<>"","Y","N") | F13: =IF('Catalog Master'!S13<>"","Y","N") | G13: =IF('Catalog Master'!X13<>"","Y","N") | H13: =IF('Catalog Master'!V13<>"","Y","N") | I13: =IF(AND('Catalog Master'!Z13<>"",'Catalog Master'!AA13<>"",'Catalog Master'!AB13<>""),"Y","N") | J13: ='Catalog Master'!N13 | K13: ='Catalog Master'!AL13 | L13: =IF(AND(E13="Y",F13="Y",G13="Y",H13="Y",I13="Y"),"Y","N")
... A334: ='Catalog Master'!A334 | B334: ='Catalog Master'!B334 | C334: ='Catalog Master'!O334 | D334: ='Catalog Master'!F334 | E334: =IF('Catalog Master'!Q334<>"","Y","N") | F334: =IF('Catalog Master'!S334<>"","Y","N") | G334: =IF('Catalog Master'!X334<>"","Y","N") | H334: =IF('Catalog Master'!V334<>"","Y","N") | I334: =IF(AND('Catalog Master'!Z334<>"",'Catalog Master'!AA334<>"",'Catalog Master'!AB334<>""),"Y","N") | J334: ='Catalog Master'!N334 | K334: ='Catalog Master'!AL334 | L334: =IF(AND(E334="Y",F334="Y",G334="Y",H334="Y",I334="Y"),"Y","N")

Sheet README
A1: Still Point Lapidary — Production Master Workbook README
A3: 1. Purpose
A4: Canonical production source of structured, operational data for all 333 Still Point Lapidary encyclopedia stones.
A5: This workbook is the operational spine for catalog identity, tiering, cohorts, navigation, chakra/energetic
A6: structured associations, hero foundation fields, image status, and production/publication status.
A8: 2. Canonical Path
A9: docs\encyclopedia\production-data\Still-Point-Lapidary-Production-Master.xlsx
A10: Keep this exact filename stable. Do not add dates, version numbers, 'final', 'updated', 'revised', or editor initials.
A11: Use dated snapshots under production-data\snapshots\ for milestone checkpoints and pre-change safety copies.
A13: 3. Source Precedence
A14: Identity spine (Stone ID, Canonical Name): this Production Master is the primary source of truth.
A15: Slugs and Previous/Next navigation: verified against 'Stones Catalog with Previous - Next Slugs.csv'
... A72: After any approved change: save the workbook, reopen, reread the changed row, and confirm the saved value.

Sheet Provenance and QA
A1: Phase 3 Reconstruction Log
A2: Reconstruction date: 2026-07-03
A3: Authorized by: Christie (Phase 3 brief, session of 2026-07-03).
A5: 1. Field-Family Source Precedence Applied
A6: Identity spine (Stone ID, Canonical Name, Alternate Names, Family, Species): live Catalog Master (Sheet1 as found), unchanged.
A7: Collection Tier, Cohort: live Catalog Master values, unchanged. Tier totals confirmed 30/132/123/48 = 333.
A8: Slug, Previous/Next Stone and Slug: live Catalog Master values, cross-verified against
A9: 'Stones Catalog with Previous - Next Slugs.csv' (data\navigation\) — 333/333 exact match on slug, name,
A10: previous slug, and next slug. Zero mismatches. Chain has exactly one start (Adamite, no Previous) and one
A11: end (Zircon, no Next); no self-references; no broken pointers.
A12: Material Type, Encyclopedia Energetic Role, Chakras, Element, Zodiac, Hero fields, workflow statuses:
A13: live Catalog Master values, unchanged. All values validated against approved controlled vocabularies.
... A75: Controlled Vocabularies exception-type list; 0 #REF! or broken formulas across all five sheets.
